<robot name = "robot">
    <link name="Link1">
        <inertial>
            <origin xyz="0 0 0.15952565704547655" rpy="0 0 0"/>
            <mass value="1" />
            <inertia ixx="100" ixy="0" ixz="0" iyy="100" iyz="0" izz="100" />
        </inertial>
        <visual>
            <origin xyz="0 0 0.15952565704547655" rpy="0 0 0"/>
            <geometry>
                <box size="0.06608473046792523 0.020500609180380436 0.3190513140909531" />
            </geometry>
            <material name="Blue">
                <color rgba="0 0.0 1.0 1.0"/>
            </material>
        </visual>
        <collision>
            <origin xyz="0 0 0.15952565704547655" rpy="0 0 0"/>
            <geometry>
                <box size="0.06608473046792523 0.020500609180380436 0.3190513140909531" />
            </geometry>
        </collision>
    </link>
    <joint name="Link1_Link2" type="revolute">
       <parent link="Link1"/>
       <child  link="Link2"/>
       <origin rpy="0 0 0" xyz="0.03304236523396262 0 0.3190513140909531" />
       <axis xyz="0 1 0"/>
       <limit effort="0.0" lower="-3.14159" upper="3.14159" velocity="0.0"/>
    </joint>
    <link name="Link2">
        <inertial>
            <origin xyz="0.21192005857073892 0 0.06796040017219418" rpy="0 0 0"/>
            <mass value="1" />
            <inertia ixx="100" ixy="0" ixz="0" iyy="100" iyz="0" izz="100" />
        </inertial>
        <visual>
            <origin xyz="0.21192005857073892 0 0.06796040017219418" rpy="0 0 0"/>
            <geometry>
                <box size="0.42384011714147785 0.2353823488694477 0.13592080034438836" />
            </geometry>
            <material name="Green">
                <color rgba="0 1.0 0.0 1.0"/>
            </material>
        </visual>
        <collision>
            <origin xyz="0.21192005857073892 0 0.06796040017219418" rpy="0 0 0"/>
            <geometry>
                <box size="0.42384011714147785 0.2353823488694477 0.13592080034438836" />
            </geometry>
        </collision>
    </link>
    <joint name="Link2_Link3" type="revolute">
       <parent link="Link2"/>
       <child  link="Link3"/>
       <origin rpy="0 0 0" xyz="0.42384011714147785 0 0.13592080034438836" />
       <axis xyz="0 1 0"/>
       <limit effort="0.0" lower="-3.14159" upper="3.14159" velocity="0.0"/>
    </joint>
    <link name="Link3">
        <inertial>
            <origin xyz="0.09435702815615998 0 0.06379514110674908" rpy="0 0 0"/>
            <mass value="1" />
            <inertia ixx="100" ixy="0" ixz="0" iyy="100" iyz="0" izz="100" />
        </inertial>
        <visual>
            <origin xyz="0.09435702815615998 0 0.06379514110674908" rpy="0 0 0"/>
            <geometry>
                <box size="0.18871405631231997 0.29145477249192236 0.12759028221349816" />
            </geometry>
            <material name="Green">
                <color rgba="0 1.0 0.0 1.0"/>
            </material>
        </visual>
        <collision>
            <origin xyz="0.09435702815615998 0 0.06379514110674908" rpy="0 0 0"/>
            <geometry>
                <box size="0.18871405631231997 0.29145477249192236 0.12759028221349816" />
            </geometry>
        </collision>
    </link>
    <joint name="Link3_Link4" type="revolute">
       <parent link="Link3"/>
       <child  link="Link4"/>
       <origin rpy="0 0 0" xyz="0.18871405631231997 0 0.12759028221349816" />
       <axis xyz="0 1 0"/>
       <limit effort="0.0" lower="-3.14159" upper="3.14159" velocity="0.0"/>
    </joint>
    <link name="Link4">
        <inertial>
            <origin xyz="0.2279381911335551 0 0.14981519770655777" rpy="0 0 0"/>
            <mass value="1" />
            <inertia ixx="100" ixy="0" ixz="0" iyy="100" iyz="0" izz="100" />
        </inertial>
        <visual>
            <origin xyz="0.2279381911335551 0 0.14981519770655777" rpy="0 0 0"/>
            <geometry>
                <box size="0.4558763822671102 0.21825181291179213 0.29963039541311554" />
            </geometry>
            <material name="Green">
                <color rgba="0 1.0 0.0 1.0"/>
            </material>
        </visual>
        <collision>
            <origin xyz="0.2279381911335551 0 0.14981519770655777" rpy="0 0 0"/>
            <geometry>
                <box size="0.4558763822671102 0.21825181291179213 0.29963039541311554" />
            </geometry>
        </collision>
    </link>
    <joint name="Link4_Link5" type="revolute">
       <parent link="Link4"/>
       <child  link="Link5"/>
       <origin rpy="0 0 0" xyz="0.4558763822671102 0 0.29963039541311554" />
       <axis xyz="0 1 0"/>
       <limit effort="0.0" lower="-3.14159" upper="3.14159" velocity="0.0"/>
    </joint>
    <link name="Link5">
        <inertial>
            <origin xyz="0.03866918985126369 0 0.06486345754898407" rpy="0 0 0"/>
            <mass value="1" />
            <inertia ixx="100" ixy="0" ixz="0" iyy="100" iyz="0" izz="100" />
        </inertial>
        <visual>
            <origin xyz="0.03866918985126369 0 0.06486345754898407" rpy="0 0 0"/>
            <geometry>
                <box size="0.07733837970252738 0.26056760554640945 0.12972691509796813" />
            </geometry>
            <material name="Green">
                <color rgba="0 1.0 0.0 1.0"/>
            </material>
        </visual>
        <collision>
            <origin xyz="0.03866918985126369 0 0.06486345754898407" rpy="0 0 0"/>
            <geometry>
                <box size="0.07733837970252738 0.26056760554640945 0.12972691509796813" />
            </geometry>
        </collision>
    </link>
    <joint name="Link5_Link6" type="revolute">
       <parent link="Link5"/>
       <child  link="Link6"/>
       <origin rpy="0 0 0" xyz="0.07733837970252738 0 0.12972691509796813" />
       <axis xyz="0 1 0"/>
       <limit effort="0.0" lower="-3.14159" upper="3.14159" velocity="0.0"/>
    </joint>
    <link name="Link6">
        <inertial>
            <origin xyz="0.028341266374359936 0 0.024448188235496632" rpy="0 0 0"/>
            <mass value="1" />
            <inertia ixx="100" ixy="0" ixz="0" iyy="100" iyz="0" izz="100" />
        </inertial>
        <visual>
            <origin xyz="0.028341266374359936 0 0.024448188235496632" rpy="0 0 0"/>
            <geometry>
                <box size="0.05668253274871987 0.1437955046651676 0.048896376470993264" />
            </geometry>
            <material name="Green">
                <color rgba="0 1.0 0.0 1.0"/>
            </material>
        </visual>
        <collision>
            <origin xyz="0.028341266374359936 0 0.024448188235496632" rpy="0 0 0"/>
            <geometry>
                <box size="0.05668253274871987 0.1437955046651676 0.048896376470993264" />
            </geometry>
        </collision>
    </link>
</robot>